[2025-02-13T06:11:45.409+0000] {local_task_job_runner.py:123} INFO - ::group::Pre task execution logs
[2025-02-13T06:11:45.438+0000] {taskinstance.py:2614} INFO - Dependencies all met for dep_context=non-requeueable deps ti=<TaskInstance: superstore_dag.run_dbt_dim_location scheduled__2025-02-12T00:00:00+00:00 [queued]>
[2025-02-13T06:11:45.459+0000] {taskinstance.py:2614} INFO - Dependencies all met for dep_context=requeueable deps ti=<TaskInstance: superstore_dag.run_dbt_dim_location scheduled__2025-02-12T00:00:00+00:00 [queued]>
[2025-02-13T06:11:45.466+0000] {taskinstance.py:2867} INFO - Starting attempt 1 of 1
[2025-02-13T06:11:45.491+0000] {taskinstance.py:2890} INFO - Executing <Task(BashOperator): run_dbt_dim_location> on 2025-02-12 00:00:00+00:00
[2025-02-13T06:11:45.508+0000] {standard_task_runner.py:72} INFO - Started process 732 to run task
[2025-02-13T06:11:45.526+0000] {standard_task_runner.py:104} INFO - Running: ['***', 'tasks', 'run', 'superstore_dag', 'run_dbt_dim_location', 'scheduled__2025-02-12T00:00:00+00:00', '--job-id', '226', '--raw', '--subdir', 'DAGS_FOLDER/superstore_dag.py', '--cfg-path', '/tmp/tmpf0f9l5cb']
[2025-02-13T06:11:45.530+0000] {standard_task_runner.py:105} INFO - Job 226: Subtask run_dbt_dim_location
[2025-02-13T06:11:45.568+0000] {logging_mixin.py:190} WARNING - /home/***/.local/lib/python3.12/site-packages/***/settings.py:209 DeprecationWarning: The sql_alchemy_conn option in [core] has been moved to the sql_alchemy_conn option in [database] - the old setting has been used, but please update your config.
[2025-02-13T06:11:45.624+0000] {task_command.py:467} INFO - Running <TaskInstance: superstore_dag.run_dbt_dim_location scheduled__2025-02-12T00:00:00+00:00 [running]> on host e06c424a4719
[2025-02-13T06:11:45.627+0000] {logging_mixin.py:190} WARNING - /home/***/.local/lib/python3.12/site-packages/***/settings.py:470 DeprecationWarning: The sql_alchemy_conn option in [core] has been moved to the sql_alchemy_conn option in [database] - the old setting has been used, but please update your config.
[2025-02-13T06:11:45.768+0000] {taskinstance.py:3134} INFO - Exporting env vars: AIRFLOW_CTX_DAG_OWNER='***' AIRFLOW_CTX_DAG_ID='superstore_dag' AIRFLOW_CTX_TASK_ID='run_dbt_dim_location' AIRFLOW_CTX_EXECUTION_DATE='2025-02-12T00:00:00+00:00' AIRFLOW_CTX_TRY_NUMBER='1' AIRFLOW_CTX_DAG_RUN_ID='scheduled__2025-02-12T00:00:00+00:00'
[2025-02-13T06:11:45.770+0000] {taskinstance.py:732} INFO - ::endgroup::
[2025-02-13T06:11:45.816+0000] {subprocess.py:78} INFO - Tmp dir root location: /tmp
[2025-02-13T06:11:45.820+0000] {subprocess.py:88} INFO - Running command: ['/usr/bin/bash', '-c', 'cd /dbt/superstore/ && dbt run --select dim_location']
[2025-02-13T06:11:45.834+0000] {subprocess.py:99} INFO - Output:
[2025-02-13T06:11:49.405+0000] {subprocess.py:106} INFO - [0m06:11:49  Running with dbt=1.9.2
[2025-02-13T06:11:49.883+0000] {subprocess.py:106} INFO - [0m06:11:49  Registered adapter: postgres=1.9.0
[2025-02-13T06:11:50.157+0000] {subprocess.py:106} INFO - [0m06:11:50  Unable to do partial parsing because profile has changed
[2025-02-13T06:11:51.645+0000] {subprocess.py:106} INFO - [0m06:11:51  [[33mWARNING[0m]: Did not find matching node for patch with name 'fact_sales' in the 'models' section of file 'models/core/schema.yml'
[2025-02-13T06:11:52.097+0000] {subprocess.py:106} INFO - [0m06:11:52  Encountered an error:
[2025-02-13T06:11:52.098+0000] {subprocess.py:106} INFO - Compilation Error
[2025-02-13T06:11:52.100+0000] {subprocess.py:106} INFO -   Model 'model.superstore_project.dim_location' (models/core/dim_location.sql) depends on a source named 'stg.superstore_data_raw' which was not found
[2025-02-13T06:11:53.325+0000] {subprocess.py:110} INFO - Command exited with return code 2
[2025-02-13T06:11:53.337+0000] {taskinstance.py:3313} ERROR - Task failed with exception
Traceback (most recent call last):
  File "/home/airflow/.local/lib/python3.12/site-packages/airflow/models/taskinstance.py", line 768, in _execute_task
    result = _execute_callable(context=context, **execute_callable_kwargs)
             ^^^^^^^^^^^^^^^^^^^^^^^^^^^^^^^^^^^^^^^^^^^^^^^^^^^^^^^^^^^^^
  File "/home/airflow/.local/lib/python3.12/site-packages/airflow/models/taskinstance.py", line 734, in _execute_callable
    return ExecutionCallableRunner(
           ^^^^^^^^^^^^^^^^^^^^^^^^
  File "/home/airflow/.local/lib/python3.12/site-packages/airflow/utils/operator_helpers.py", line 252, in run
    return self.func(*args, **kwargs)
           ^^^^^^^^^^^^^^^^^^^^^^^^^^
  File "/home/airflow/.local/lib/python3.12/site-packages/airflow/models/baseoperator.py", line 424, in wrapper
    return func(self, *args, **kwargs)
           ^^^^^^^^^^^^^^^^^^^^^^^^^^^
  File "/home/airflow/.local/lib/python3.12/site-packages/airflow/operators/bash.py", line 276, in execute
    raise AirflowException(
airflow.exceptions.AirflowException: Bash command failed. The command returned a non-zero exit code 2.
[2025-02-13T06:11:53.349+0000] {taskinstance.py:1226} INFO - Marking task as FAILED. dag_id=superstore_dag, task_id=run_dbt_dim_location, run_id=scheduled__2025-02-12T00:00:00+00:00, execution_date=20250212T000000, start_date=20250213T061145, end_date=20250213T061153
[2025-02-13T06:11:53.384+0000] {taskinstance.py:341} INFO - ::group::Post task execution logs
[2025-02-13T06:11:53.385+0000] {standard_task_runner.py:124} ERROR - Failed to execute job 226 for task run_dbt_dim_location (Bash command failed. The command returned a non-zero exit code 2.; 732)
Traceback (most recent call last):
  File "/home/airflow/.local/lib/python3.12/site-packages/airflow/task/task_runner/standard_task_runner.py", line 117, in _start_by_fork
    ret = args.func(args, dag=self.dag)
          ^^^^^^^^^^^^^^^^^^^^^^^^^^^^^
  File "/home/airflow/.local/lib/python3.12/site-packages/airflow/cli/cli_config.py", line 49, in command
    return func(*args, **kwargs)
           ^^^^^^^^^^^^^^^^^^^^^
  File "/home/airflow/.local/lib/python3.12/site-packages/airflow/utils/cli.py", line 116, in wrapper
    return f(*args, **kwargs)
           ^^^^^^^^^^^^^^^^^^
  File "/home/airflow/.local/lib/python3.12/site-packages/airflow/cli/commands/task_command.py", line 483, in task_run
    task_return_code = _run_task_by_selected_method(args, _dag, ti)
                       ^^^^^^^^^^^^^^^^^^^^^^^^^^^^^^^^^^^^^^^^^^^^
  File "/home/airflow/.local/lib/python3.12/site-packages/airflow/cli/commands/task_command.py", line 256, in _run_task_by_selected_method
    return _run_raw_task(args, ti)
           ^^^^^^^^^^^^^^^^^^^^^^^
  File "/home/airflow/.local/lib/python3.12/site-packages/airflow/cli/commands/task_command.py", line 341, in _run_raw_task
    return ti._run_raw_task(
           ^^^^^^^^^^^^^^^^^
  File "/home/airflow/.local/lib/python3.12/site-packages/airflow/utils/session.py", line 97, in wrapper
    return func(*args, session=session, **kwargs)
           ^^^^^^^^^^^^^^^^^^^^^^^^^^^^^^^^^^^^^^
  File "/home/airflow/.local/lib/python3.12/site-packages/airflow/models/taskinstance.py", line 3006, in _run_raw_task
    return _run_raw_task(
           ^^^^^^^^^^^^^^
  File "/home/airflow/.local/lib/python3.12/site-packages/airflow/models/taskinstance.py", line 274, in _run_raw_task
    TaskInstance._execute_task_with_callbacks(
  File "/home/airflow/.local/lib/python3.12/site-packages/airflow/models/taskinstance.py", line 3161, in _execute_task_with_callbacks
    result = self._execute_task(context, task_orig)
             ^^^^^^^^^^^^^^^^^^^^^^^^^^^^^^^^^^^^^^
  File "/home/airflow/.local/lib/python3.12/site-packages/airflow/models/taskinstance.py", line 3185, in _execute_task
    return _execute_task(self, context, task_orig)
           ^^^^^^^^^^^^^^^^^^^^^^^^^^^^^^^^^^^^^^^
  File "/home/airflow/.local/lib/python3.12/site-packages/airflow/models/taskinstance.py", line 768, in _execute_task
    result = _execute_callable(context=context, **execute_callable_kwargs)
             ^^^^^^^^^^^^^^^^^^^^^^^^^^^^^^^^^^^^^^^^^^^^^^^^^^^^^^^^^^^^^
  File "/home/airflow/.local/lib/python3.12/site-packages/airflow/models/taskinstance.py", line 734, in _execute_callable
    return ExecutionCallableRunner(
           ^^^^^^^^^^^^^^^^^^^^^^^^
  File "/home/airflow/.local/lib/python3.12/site-packages/airflow/utils/operator_helpers.py", line 252, in run
    return self.func(*args, **kwargs)
           ^^^^^^^^^^^^^^^^^^^^^^^^^^
  File "/home/airflow/.local/lib/python3.12/site-packages/airflow/models/baseoperator.py", line 424, in wrapper
    return func(self, *args, **kwargs)
           ^^^^^^^^^^^^^^^^^^^^^^^^^^^
  File "/home/airflow/.local/lib/python3.12/site-packages/airflow/operators/bash.py", line 276, in execute
    raise AirflowException(
airflow.exceptions.AirflowException: Bash command failed. The command returned a non-zero exit code 2.
[2025-02-13T06:11:53.404+0000] {local_task_job_runner.py:266} INFO - Task exited with return code 1
[2025-02-13T06:11:53.430+0000] {taskinstance.py:3901} INFO - 0 downstream tasks scheduled from follow-on schedule check
[2025-02-13T06:11:53.434+0000] {local_task_job_runner.py:245} INFO - ::endgroup::
