[2025-02-08T16:47:56.326+0000] {local_task_job_runner.py:123} INFO - ::group::Pre task execution logs
[2025-02-08T16:47:56.338+0000] {taskinstance.py:2613} INFO - Dependencies all met for dep_context=non-requeueable deps ti=<TaskInstance: dim_location.run_dbt_dim_location scheduled__2025-02-07T00:00:00+00:00 [queued]>
[2025-02-08T16:47:56.344+0000] {taskinstance.py:2613} INFO - Dependencies all met for dep_context=requeueable deps ti=<TaskInstance: dim_location.run_dbt_dim_location scheduled__2025-02-07T00:00:00+00:00 [queued]>
[2025-02-08T16:47:56.345+0000] {taskinstance.py:2866} INFO - Starting attempt 1 of 1
[2025-02-08T16:47:56.355+0000] {taskinstance.py:2889} INFO - Executing <Task(BashOperator): run_dbt_dim_location> on 2025-02-07 00:00:00+00:00
[2025-02-08T16:47:56.359+0000] {standard_task_runner.py:72} INFO - Started process 143 to run task
[2025-02-08T16:47:56.361+0000] {standard_task_runner.py:104} INFO - Running: ['***', 'tasks', 'run', 'dim_location', 'run_dbt_dim_location', 'scheduled__2025-02-07T00:00:00+00:00', '--job-id', '175', '--raw', '--subdir', 'DAGS_FOLDER/dim_location.py', '--cfg-path', '/tmp/tmp_tctk_8o']
[2025-02-08T16:47:56.365+0000] {standard_task_runner.py:105} INFO - Job 175: Subtask run_dbt_dim_location
[2025-02-08T16:47:56.384+0000] {logging_mixin.py:190} WARNING - /home/***/.local/lib/python3.12/site-packages/***/settings.py:209 DeprecationWarning: The sql_alchemy_conn option in [core] has been moved to the sql_alchemy_conn option in [database] - the old setting has been used, but please update your config.
[2025-02-08T16:47:56.416+0000] {task_command.py:467} INFO - Running <TaskInstance: dim_location.run_dbt_dim_location scheduled__2025-02-07T00:00:00+00:00 [running]> on host 9cd0ccfaeb2e
[2025-02-08T16:47:56.419+0000] {logging_mixin.py:190} WARNING - /home/***/.local/lib/python3.12/site-packages/***/settings.py:470 DeprecationWarning: The sql_alchemy_conn option in [core] has been moved to the sql_alchemy_conn option in [database] - the old setting has been used, but please update your config.
[2025-02-08T16:47:56.509+0000] {taskinstance.py:3132} INFO - Exporting env vars: AIRFLOW_CTX_DAG_OWNER='***' AIRFLOW_CTX_DAG_ID='dim_location' AIRFLOW_CTX_TASK_ID='run_dbt_dim_location' AIRFLOW_CTX_EXECUTION_DATE='2025-02-07T00:00:00+00:00' AIRFLOW_CTX_TRY_NUMBER='1' AIRFLOW_CTX_DAG_RUN_ID='scheduled__2025-02-07T00:00:00+00:00'
[2025-02-08T16:47:56.510+0000] {taskinstance.py:731} INFO - ::endgroup::
[2025-02-08T16:47:56.550+0000] {subprocess.py:78} INFO - Tmp dir root location: /tmp
[2025-02-08T16:47:56.551+0000] {subprocess.py:88} INFO - Running command: ['/usr/bin/bash', '-c', 'dbt run --select dim_location']
[2025-02-08T16:47:56.560+0000] {subprocess.py:99} INFO - Output:
[2025-02-08T16:47:58.764+0000] {subprocess.py:106} INFO - [0m16:47:58  Running with dbt=1.9.2
[2025-02-08T16:47:58.765+0000] {subprocess.py:106} INFO - [0m16:47:58  Encountered an error:
[2025-02-08T16:47:58.765+0000] {subprocess.py:106} INFO - Runtime Error
[2025-02-08T16:47:58.765+0000] {subprocess.py:106} INFO -   No dbt_project.yml found at expected path /tmp/***tmpxjwx3sxv/dbt_project.yml
[2025-02-08T16:47:58.766+0000] {subprocess.py:106} INFO -   Verify that each entry within packages.yml (and their transitive dependencies) contains a file named dbt_project.yml
[2025-02-08T16:47:58.766+0000] {subprocess.py:106} INFO - 
[2025-02-08T16:47:59.643+0000] {subprocess.py:110} INFO - Command exited with return code 2
[2025-02-08T16:47:59.653+0000] {taskinstance.py:3311} ERROR - Task failed with exception
Traceback (most recent call last):
  File "/home/airflow/.local/lib/python3.12/site-packages/airflow/models/taskinstance.py", line 767, in _execute_task
    result = _execute_callable(context=context, **execute_callable_kwargs)
             ^^^^^^^^^^^^^^^^^^^^^^^^^^^^^^^^^^^^^^^^^^^^^^^^^^^^^^^^^^^^^
  File "/home/airflow/.local/lib/python3.12/site-packages/airflow/models/taskinstance.py", line 733, in _execute_callable
    return ExecutionCallableRunner(
           ^^^^^^^^^^^^^^^^^^^^^^^^
  File "/home/airflow/.local/lib/python3.12/site-packages/airflow/utils/operator_helpers.py", line 252, in run
    return self.func(*args, **kwargs)
           ^^^^^^^^^^^^^^^^^^^^^^^^^^
  File "/home/airflow/.local/lib/python3.12/site-packages/airflow/models/baseoperator.py", line 422, in wrapper
    return func(self, *args, **kwargs)
           ^^^^^^^^^^^^^^^^^^^^^^^^^^^
  File "/home/airflow/.local/lib/python3.12/site-packages/airflow/operators/bash.py", line 276, in execute
    raise AirflowException(
airflow.exceptions.AirflowException: Bash command failed. The command returned a non-zero exit code 2.
[2025-02-08T16:47:59.658+0000] {taskinstance.py:1225} INFO - Marking task as FAILED. dag_id=dim_location, task_id=run_dbt_dim_location, run_id=scheduled__2025-02-07T00:00:00+00:00, execution_date=20250207T000000, start_date=20250208T164756, end_date=20250208T164759
[2025-02-08T16:47:59.668+0000] {taskinstance.py:340} INFO - ::group::Post task execution logs
[2025-02-08T16:47:59.669+0000] {standard_task_runner.py:124} ERROR - Failed to execute job 175 for task run_dbt_dim_location (Bash command failed. The command returned a non-zero exit code 2.; 143)
Traceback (most recent call last):
  File "/home/airflow/.local/lib/python3.12/site-packages/airflow/task/task_runner/standard_task_runner.py", line 117, in _start_by_fork
    ret = args.func(args, dag=self.dag)
          ^^^^^^^^^^^^^^^^^^^^^^^^^^^^^
  File "/home/airflow/.local/lib/python3.12/site-packages/airflow/cli/cli_config.py", line 49, in command
    return func(*args, **kwargs)
           ^^^^^^^^^^^^^^^^^^^^^
  File "/home/airflow/.local/lib/python3.12/site-packages/airflow/utils/cli.py", line 116, in wrapper
    return f(*args, **kwargs)
           ^^^^^^^^^^^^^^^^^^
  File "/home/airflow/.local/lib/python3.12/site-packages/airflow/cli/commands/task_command.py", line 483, in task_run
    task_return_code = _run_task_by_selected_method(args, _dag, ti)
                       ^^^^^^^^^^^^^^^^^^^^^^^^^^^^^^^^^^^^^^^^^^^^
  File "/home/airflow/.local/lib/python3.12/site-packages/airflow/cli/commands/task_command.py", line 256, in _run_task_by_selected_method
    return _run_raw_task(args, ti)
           ^^^^^^^^^^^^^^^^^^^^^^^
  File "/home/airflow/.local/lib/python3.12/site-packages/airflow/cli/commands/task_command.py", line 341, in _run_raw_task
    return ti._run_raw_task(
           ^^^^^^^^^^^^^^^^^
  File "/home/airflow/.local/lib/python3.12/site-packages/airflow/utils/session.py", line 97, in wrapper
    return func(*args, session=session, **kwargs)
           ^^^^^^^^^^^^^^^^^^^^^^^^^^^^^^^^^^^^^^
  File "/home/airflow/.local/lib/python3.12/site-packages/airflow/models/taskinstance.py", line 3005, in _run_raw_task
    return _run_raw_task(
           ^^^^^^^^^^^^^^
  File "/home/airflow/.local/lib/python3.12/site-packages/airflow/models/taskinstance.py", line 273, in _run_raw_task
    TaskInstance._execute_task_with_callbacks(
  File "/home/airflow/.local/lib/python3.12/site-packages/airflow/models/taskinstance.py", line 3159, in _execute_task_with_callbacks
    result = self._execute_task(context, task_orig)
             ^^^^^^^^^^^^^^^^^^^^^^^^^^^^^^^^^^^^^^
  File "/home/airflow/.local/lib/python3.12/site-packages/airflow/models/taskinstance.py", line 3183, in _execute_task
    return _execute_task(self, context, task_orig)
           ^^^^^^^^^^^^^^^^^^^^^^^^^^^^^^^^^^^^^^^
  File "/home/airflow/.local/lib/python3.12/site-packages/airflow/models/taskinstance.py", line 767, in _execute_task
    result = _execute_callable(context=context, **execute_callable_kwargs)
             ^^^^^^^^^^^^^^^^^^^^^^^^^^^^^^^^^^^^^^^^^^^^^^^^^^^^^^^^^^^^^
  File "/home/airflow/.local/lib/python3.12/site-packages/airflow/models/taskinstance.py", line 733, in _execute_callable
    return ExecutionCallableRunner(
           ^^^^^^^^^^^^^^^^^^^^^^^^
  File "/home/airflow/.local/lib/python3.12/site-packages/airflow/utils/operator_helpers.py", line 252, in run
    return self.func(*args, **kwargs)
           ^^^^^^^^^^^^^^^^^^^^^^^^^^
  File "/home/airflow/.local/lib/python3.12/site-packages/airflow/models/baseoperator.py", line 422, in wrapper
    return func(self, *args, **kwargs)
           ^^^^^^^^^^^^^^^^^^^^^^^^^^^
  File "/home/airflow/.local/lib/python3.12/site-packages/airflow/operators/bash.py", line 276, in execute
    raise AirflowException(
airflow.exceptions.AirflowException: Bash command failed. The command returned a non-zero exit code 2.
[2025-02-08T16:47:59.702+0000] {local_task_job_runner.py:266} INFO - Task exited with return code 1
[2025-02-08T16:47:59.714+0000] {taskinstance.py:3895} INFO - 0 downstream tasks scheduled from follow-on schedule check
[2025-02-08T16:47:59.716+0000] {local_task_job_runner.py:245} INFO - ::endgroup::
