[2025-02-15T21:45:33.291+0000] {local_task_job_runner.py:123} INFO - ::group::Pre task execution logs
[2025-02-15T21:45:33.305+0000] {taskinstance.py:2614} INFO - Dependencies all met for dep_context=non-requeueable deps ti=<TaskInstance: superstore_dag.run_dbt_dim_location scheduled__2025-02-14T00:00:00+00:00 [queued]>
[2025-02-15T21:45:33.311+0000] {taskinstance.py:2614} INFO - Dependencies all met for dep_context=requeueable deps ti=<TaskInstance: superstore_dag.run_dbt_dim_location scheduled__2025-02-14T00:00:00+00:00 [queued]>
[2025-02-15T21:45:33.312+0000] {taskinstance.py:2867} INFO - Starting attempt 1 of 1
[2025-02-15T21:45:33.323+0000] {taskinstance.py:2890} INFO - Executing <Task(BashOperator): run_dbt_dim_location> on 2025-02-14 00:00:00+00:00
[2025-02-15T21:45:33.328+0000] {standard_task_runner.py:72} INFO - Started process 229 to run task
[2025-02-15T21:45:33.330+0000] {standard_task_runner.py:104} INFO - Running: ['***', 'tasks', 'run', 'superstore_dag', 'run_dbt_dim_location', 'scheduled__2025-02-14T00:00:00+00:00', '--job-id', '235', '--raw', '--subdir', 'DAGS_FOLDER/superstore_dag.py', '--cfg-path', '/tmp/tmpxvacfg0r']
[2025-02-15T21:45:33.332+0000] {standard_task_runner.py:105} INFO - Job 235: Subtask run_dbt_dim_location
[2025-02-15T21:45:33.345+0000] {logging_mixin.py:190} WARNING - /home/***/.local/lib/python3.12/site-packages/***/settings.py:209 DeprecationWarning: The sql_alchemy_conn option in [core] has been moved to the sql_alchemy_conn option in [database] - the old setting has been used, but please update your config.
[2025-02-15T21:45:33.375+0000] {task_command.py:467} INFO - Running <TaskInstance: superstore_dag.run_dbt_dim_location scheduled__2025-02-14T00:00:00+00:00 [running]> on host e06c424a4719
[2025-02-15T21:45:33.377+0000] {logging_mixin.py:190} WARNING - /home/***/.local/lib/python3.12/site-packages/***/settings.py:470 DeprecationWarning: The sql_alchemy_conn option in [core] has been moved to the sql_alchemy_conn option in [database] - the old setting has been used, but please update your config.
[2025-02-15T21:45:33.454+0000] {taskinstance.py:3134} INFO - Exporting env vars: AIRFLOW_CTX_DAG_OWNER='***' AIRFLOW_CTX_DAG_ID='superstore_dag' AIRFLOW_CTX_TASK_ID='run_dbt_dim_location' AIRFLOW_CTX_EXECUTION_DATE='2025-02-14T00:00:00+00:00' AIRFLOW_CTX_TRY_NUMBER='1' AIRFLOW_CTX_DAG_RUN_ID='scheduled__2025-02-14T00:00:00+00:00'
[2025-02-15T21:45:33.455+0000] {taskinstance.py:732} INFO - ::endgroup::
[2025-02-15T21:45:33.473+0000] {subprocess.py:78} INFO - Tmp dir root location: /tmp
[2025-02-15T21:45:33.474+0000] {subprocess.py:88} INFO - Running command: ['/usr/bin/bash', '-c', 'cd /dbt/superstore/ && dbt run --select dim_location']
[2025-02-15T21:45:33.482+0000] {subprocess.py:99} INFO - Output:
[2025-02-15T21:45:35.633+0000] {subprocess.py:106} INFO - [0m21:45:35  Running with dbt=1.9.2
[2025-02-15T21:45:35.949+0000] {subprocess.py:106} INFO - [0m21:45:35  Registered adapter: postgres=1.9.0
[2025-02-15T21:45:36.135+0000] {subprocess.py:106} INFO - [0m21:45:36  Unable to do partial parsing because profile has changed
[2025-02-15T21:45:37.421+0000] {subprocess.py:106} INFO - [0m21:45:37  [[33mWARNING[0m]: Did not find matching node for patch with name 'fact_sales' in the 'models' section of file 'models/core/schema.yml'
[2025-02-15T21:45:37.860+0000] {subprocess.py:106} INFO - [0m21:45:37  Encountered an error:
[2025-02-15T21:45:37.861+0000] {subprocess.py:106} INFO - Compilation Error
[2025-02-15T21:45:37.862+0000] {subprocess.py:106} INFO -   Model 'model.superstore_project.dim_location' (models/core/dim_location.sql) depends on a source named 'stg.superstore_data_raw' which was not found
[2025-02-15T21:45:38.859+0000] {subprocess.py:110} INFO - Command exited with return code 2
[2025-02-15T21:45:38.871+0000] {taskinstance.py:3313} ERROR - Task failed with exception
Traceback (most recent call last):
  File "/home/airflow/.local/lib/python3.12/site-packages/airflow/models/taskinstance.py", line 768, in _execute_task
    result = _execute_callable(context=context, **execute_callable_kwargs)
             ^^^^^^^^^^^^^^^^^^^^^^^^^^^^^^^^^^^^^^^^^^^^^^^^^^^^^^^^^^^^^
  File "/home/airflow/.local/lib/python3.12/site-packages/airflow/models/taskinstance.py", line 734, in _execute_callable
    return ExecutionCallableRunner(
           ^^^^^^^^^^^^^^^^^^^^^^^^
  File "/home/airflow/.local/lib/python3.12/site-packages/airflow/utils/operator_helpers.py", line 252, in run
    return self.func(*args, **kwargs)
           ^^^^^^^^^^^^^^^^^^^^^^^^^^
  File "/home/airflow/.local/lib/python3.12/site-packages/airflow/models/baseoperator.py", line 424, in wrapper
    return func(self, *args, **kwargs)
           ^^^^^^^^^^^^^^^^^^^^^^^^^^^
  File "/home/airflow/.local/lib/python3.12/site-packages/airflow/operators/bash.py", line 276, in execute
    raise AirflowException(
airflow.exceptions.AirflowException: Bash command failed. The command returned a non-zero exit code 2.
[2025-02-15T21:45:38.876+0000] {taskinstance.py:1226} INFO - Marking task as FAILED. dag_id=superstore_dag, task_id=run_dbt_dim_location, run_id=scheduled__2025-02-14T00:00:00+00:00, execution_date=20250214T000000, start_date=20250215T214533, end_date=20250215T214538
[2025-02-15T21:45:38.901+0000] {taskinstance.py:341} INFO - ::group::Post task execution logs
[2025-02-15T21:45:38.901+0000] {standard_task_runner.py:124} ERROR - Failed to execute job 235 for task run_dbt_dim_location (Bash command failed. The command returned a non-zero exit code 2.; 229)
Traceback (most recent call last):
  File "/home/airflow/.local/lib/python3.12/site-packages/airflow/task/task_runner/standard_task_runner.py", line 117, in _start_by_fork
    ret = args.func(args, dag=self.dag)
          ^^^^^^^^^^^^^^^^^^^^^^^^^^^^^
  File "/home/airflow/.local/lib/python3.12/site-packages/airflow/cli/cli_config.py", line 49, in command
    return func(*args, **kwargs)
           ^^^^^^^^^^^^^^^^^^^^^
  File "/home/airflow/.local/lib/python3.12/site-packages/airflow/utils/cli.py", line 116, in wrapper
    return f(*args, **kwargs)
           ^^^^^^^^^^^^^^^^^^
  File "/home/airflow/.local/lib/python3.12/site-packages/airflow/cli/commands/task_command.py", line 483, in task_run
    task_return_code = _run_task_by_selected_method(args, _dag, ti)
                       ^^^^^^^^^^^^^^^^^^^^^^^^^^^^^^^^^^^^^^^^^^^^
  File "/home/airflow/.local/lib/python3.12/site-packages/airflow/cli/commands/task_command.py", line 256, in _run_task_by_selected_method
    return _run_raw_task(args, ti)
           ^^^^^^^^^^^^^^^^^^^^^^^
  File "/home/airflow/.local/lib/python3.12/site-packages/airflow/cli/commands/task_command.py", line 341, in _run_raw_task
    return ti._run_raw_task(
           ^^^^^^^^^^^^^^^^^
  File "/home/airflow/.local/lib/python3.12/site-packages/airflow/utils/session.py", line 97, in wrapper
    return func(*args, session=session, **kwargs)
           ^^^^^^^^^^^^^^^^^^^^^^^^^^^^^^^^^^^^^^
  File "/home/airflow/.local/lib/python3.12/site-packages/airflow/models/taskinstance.py", line 3006, in _run_raw_task
    return _run_raw_task(
           ^^^^^^^^^^^^^^
  File "/home/airflow/.local/lib/python3.12/site-packages/airflow/models/taskinstance.py", line 274, in _run_raw_task
    TaskInstance._execute_task_with_callbacks(
  File "/home/airflow/.local/lib/python3.12/site-packages/airflow/models/taskinstance.py", line 3161, in _execute_task_with_callbacks
    result = self._execute_task(context, task_orig)
             ^^^^^^^^^^^^^^^^^^^^^^^^^^^^^^^^^^^^^^
  File "/home/airflow/.local/lib/python3.12/site-packages/airflow/models/taskinstance.py", line 3185, in _execute_task
    return _execute_task(self, context, task_orig)
           ^^^^^^^^^^^^^^^^^^^^^^^^^^^^^^^^^^^^^^^
  File "/home/airflow/.local/lib/python3.12/site-packages/airflow/models/taskinstance.py", line 768, in _execute_task
    result = _execute_callable(context=context, **execute_callable_kwargs)
             ^^^^^^^^^^^^^^^^^^^^^^^^^^^^^^^^^^^^^^^^^^^^^^^^^^^^^^^^^^^^^
  File "/home/airflow/.local/lib/python3.12/site-packages/airflow/models/taskinstance.py", line 734, in _execute_callable
    return ExecutionCallableRunner(
           ^^^^^^^^^^^^^^^^^^^^^^^^
  File "/home/airflow/.local/lib/python3.12/site-packages/airflow/utils/operator_helpers.py", line 252, in run
    return self.func(*args, **kwargs)
           ^^^^^^^^^^^^^^^^^^^^^^^^^^
  File "/home/airflow/.local/lib/python3.12/site-packages/airflow/models/baseoperator.py", line 424, in wrapper
    return func(self, *args, **kwargs)
           ^^^^^^^^^^^^^^^^^^^^^^^^^^^
  File "/home/airflow/.local/lib/python3.12/site-packages/airflow/operators/bash.py", line 276, in execute
    raise AirflowException(
airflow.exceptions.AirflowException: Bash command failed. The command returned a non-zero exit code 2.
[2025-02-15T21:45:38.928+0000] {local_task_job_runner.py:266} INFO - Task exited with return code 1
[2025-02-15T21:45:38.953+0000] {taskinstance.py:3901} INFO - 0 downstream tasks scheduled from follow-on schedule check
[2025-02-15T21:45:38.957+0000] {local_task_job_runner.py:245} INFO - ::endgroup::
